<?xml version="1.0" ?>
<robot name="amr" xmlns:xacro="http://ros.org/wiki/xacro">
  <xacro:include filename="$(find amr_description)/urdf/amr.gazebo_red.xacro"/>

  <link name="base_link">
    <visual>
      <origin xyz="0 0 0" rpy="0 0 0"/>
      <geometry>
        <mesh filename="package://amr_description/meshes/base.stl" scale="0.001 0.001 0.001"/>
      </geometry>
    </visual>

    <collision>
      <origin xyz="0.0 0 0.07" rpy="0 0 0"/>
      <geometry>
        <box size="0.48 0.36 0.14"/>
      </geometry>
    </collision>
    
    <inertial>
      <origin xyz="0 0 0.0" rpy="0 0 0"/>
      <mass value="40"/>
      <inertia ixx="0.33" ixy="0" ixz="0" iyy="0.54" iyz="0" izz="0.77"/>
    </inertial>
  </link>
  
  <joint name="bumper_joint" type="fixed">
    <parent link="base_link"/>
    <child link="bumper_link"/>
    <origin xyz="0 0 0" rpy="0 0 0"/>
  </joint>
  
  <link name="bumper_link">
    <visual>
      <origin xyz="0 0 0" rpy="0 0 0"/>
      <geometry>
        <mesh filename="package://amr_description/meshes/bumper.stl" scale="0.001 0.001 0.001"/>
      </geometry>
    </visual>

    <collision>
      <origin xyz="0 0 -0.011" rpy="0 0 0"/>
      <geometry>
        <box size="0.59 0.46 0.022"/>
      </geometry>
    </collision>
    
    <inertial>
      <origin xyz="0 0 0" rpy="0 0 0"/>
      <mass value="2.0"/>
      <inertia ixx="0.1" ixy="0" ixz="0" iyy="0.15" iyz="0" izz="0.2"/>
    </inertial>
  </link>
   <!--
  <joint name="plate_joint1" type="fixed">
    <parent link="base_link"/>
    <child link="plate_link1"/>
    <origin xyz="0 0 0" rpy="0 0 0"/>
  </joint>
  
  <link name="plate_link1">
    <visual>
      <origin xyz="0 0 0" rpy="0 0 0"/>
      <geometry>
        <mesh filename="package://amr_description/meshes/top_plate.stl" scale="0.001 0.001 0.001"/>
      </geometry>
    </visual>
    
    <collision>
      <origin xyz="0.076 0 0.187" rpy="0 0 0"/>
      <geometry>
        <box size="0.26 0.18 0.002"/>
      </geometry>
    </collision>

    <collision>
      <origin xyz="0.076 0 0.239" rpy="0 0 0"/>
      <geometry>
        <box size="0.26 0.18 0.002"/>
      </geometry>
    </collision>
    
    <collision>
      <origin xyz="0.076 0 0.291" rpy="0 0 0"/>
      <geometry>
        <box size="0.26 0.18 0.002"/>
      </geometry>
    </collision>
    
    <collision>
      <origin xyz="-0.044 0.08 0.213" rpy="0 0 0"/>
      <geometry>
        <cylinder length="0.16" radius="0.004"/>
      </geometry>
    </collision>
    
    <collision>
      <origin xyz="-0.044 -0.08 0.213" rpy="0 0 0"/>
      <geometry>
        <cylinder length="0.16" radius="0.004"/>
      </geometry>
    </collision>
    
    <collision>
      <origin xyz="0.196 -0.08 0.213" rpy="0 0 0"/>
      <geometry>
        <cylinder length="0.16" radius="0.004"/>
      </geometry>
    </collision>
    
    <collision>
      <origin xyz="0.196 0.08 0.213" rpy="0 0 0"/>
      <geometry>
        <cylinder length="0.16" radius="0.004"/>
      </geometry>
    </collision>
    
    <inertial>
      <origin xyz="0.076 0 0.2" rpy="0 0 0"/>
      <mass value="0.5"/>
      <inertia ixx="0.014" ixy="0" ixz="0" iyy="0.024" iyz="0" izz="0.028"/>
    </inertial>
  </link>
 
   <joint name="plate_joint2" type="fixed">
    <parent link="base_link"/>
    <child link="plate_link2"/>
    <origin xyz="0 0 0.156" rpy="0 0 0"/>
  </joint>
  
  <link name="plate_link2">
    <visual>
      <origin xyz="0 0 0" rpy="0 0 0"/>
      <geometry>
        <mesh filename="package://amr_description/meshes/top_plate.stl" scale="0.001 0.001 0.001"/>
      </geometry>
    </visual>
    
    <collision>
      <origin xyz="0.076 0 0.187" rpy="0 0 0"/>
      <geometry>
        <box size="0.26 0.18 0.002"/>
      </geometry>
    </collision>

    <collision>
      <origin xyz="0.076 0 0.239" rpy="0 0 0"/>
      <geometry>
        <box size="0.26 0.18 0.002"/>
      </geometry>
    </collision>
    
    <collision>
      <origin xyz="0.076 0 0.291" rpy="0 0 0"/>
      <geometry>
        <box size="0.26 0.18 0.002"/>
      </geometry>
    </collision>
    
    <collision>
      <origin xyz="-0.044 0.08 0.213" rpy="0 0 0"/>
      <geometry>
        <cylinder length="0.16" radius="0.004"/>
      </geometry>
    </collision>
    
    <collision>
      <origin xyz="-0.044 -0.08 0.213" rpy="0 0 0"/>
      <geometry>
        <cylinder length="0.16" radius="0.004"/>
      </geometry>
    </collision>
    
    <collision>
      <origin xyz="0.196 -0.08 0.213" rpy="0 0 0"/>
      <geometry>
        <cylinder length="0.16" radius="0.004"/>
      </geometry>
    </collision>
    
    <collision>
      <origin xyz="0.196 0.08 0.213" rpy="0 0 0"/>
      <geometry>
        <cylinder length="0.16" radius="0.004"/>
      </geometry>
    </collision>
    
    <inertial>
      <origin xyz="0.076 0 0.2" rpy="0 0 0"/>
      <mass value="0.5"/>
      <inertia ixx="0.014" ixy="0" ixz="0" iyy="0.024" iyz="0" izz="0.028"/>
    </inertial>
  </link>
  -->
  <joint name="wheel_fl_axle_joint" type="fixed">
      <origin xyz="0.161 0.167 0.036" rpy="0 0 0"/>
      <parent link="base_link"/>
      <child link="wheel_fl_axle_link"/>
  </joint>
  
  <link name="wheel_fl_axle_link">
    <inertial>
      <mass value="0.1"/>
      <origin xyz="0 0 0"/>
      <inertia ixx="1.0" ixy="0.0" ixz="0.0" iyy="1.0" iyz="0.0" izz="1.0"/>
    </inertial>
    
    <collision>
        <origin xyz="0 0 0" rpy="1.57 0 0"/>
        <geometry>
        <cylinder length="0.03" radius="0.01"/>
      </geometry>
    </collision>
  </link>

  <joint name="wheel_fl_joint" type="continuous">
    <parent link="wheel_fl_axle_link"/>
    <child link="wheel_fl_link"/>
    <origin xyz="0 0 0" rpy="0 0 0"/>
    <axis xyz="0 1 0"/>
    <dynamics damping="0.02" friction="0.01"/>
  </joint>

  <link name="wheel_fl_link">
    <visual>
      <origin xyz="0 0 0" rpy="0 0 0"/>
      <geometry>
        <mesh filename="package://amr_description/meshes/wheel.stl" scale="0.001 0.001 0.001"/>
      </geometry>
    </visual>

    <collision>
      <origin xyz="0 0 0" rpy="1.57 0 0"/>
      <geometry>
        <cylinder length="0.053" radius="0.072"/>
      </geometry>
    </collision>

    <inertial>
      <origin xyz="0 0 0" />
      <mass value="1.12" />
      <inertia ixx="0.0012" ixy="0" ixz="0.0" iyy="0.0021" iyz="0" izz="0.0012"/>
    </inertial>
  </link>
  
  <joint name="wheel_fr_axle_joint" type="fixed">
      <origin xyz="0.161 -0.167 0.036" rpy="0 0 0"/>
      <parent link="base_link"/>
      <child link="wheel_fr_axle_link"/>
  </joint>
  
  <link name="wheel_fr_axle_link">
    <inertial>
      <mass value="0.1"/>
      <origin xyz="0 0 0"/>
      <inertia ixx="1.0" ixy="0.0" ixz="0.0" iyy="1.0" iyz="0.0" izz="1.0"/>
    </inertial>
    
    <collision>
        <origin xyz="0 0 0" rpy="1.57 0 0"/>
        <geometry>
        <cylinder length="0.03" radius="0.01"/>
      </geometry>
    </collision>
  </link>

  <joint name="wheel_fr_joint" type="continuous">
    <parent link="wheel_fr_axle_link"/>
    <child link="wheel_fr_link"/>
    <origin xyz="0 0 0" rpy="0 0 0"/>
    <axis xyz="0 1 0"/>
    <dynamics damping="0.02" friction="0.01"/>
  </joint>

  <link name="wheel_fr_link">
    <visual>
      <origin xyz="0 0 0" rpy="0 0 0"/>
      <geometry>
        <mesh filename="package://amr_description/meshes/wheel.stl" scale="0.001 0.001 0.001"/>
      </geometry>
    </visual>

    <collision>
      <origin xyz="0 0 0" rpy="1.57 0 0"/>
      <geometry>
        <cylinder length="0.053" radius="0.072"/>
      </geometry>
    </collision>

    <inertial>
      <origin xyz="0 0 0" />
      <mass value="1.12" />
      <inertia ixx="0.0012" ixy="0" ixz="0.0" iyy="0.0021" iyz="0" izz="0.0012"/>
    </inertial>
  </link>
  
  <joint name="wheel_rl_axle_joint" type="fixed">
      <origin xyz="-0.161 0.167 0.036" rpy="0 0 0"/>
      <parent link="base_link"/>
      <child link="wheel_rl_axle_link"/>
  </joint>
  
  <link name="wheel_rl_axle_link">
    <inertial>
      <mass value="0.1"/>
      <origin xyz="0 0 0"/>
      <inertia ixx="1.0" ixy="0.0" ixz="0.0" iyy="1.0" iyz="0.0" izz="1.0"/>
    </inertial>
    <collision>
        <origin xyz="0 0 0" rpy="1.57 0 0"/>
        <geometry>
        <cylinder length="0.03" radius="0.01"/>
      </geometry>
    </collision>
  </link>
  
  <joint name="wheel_rl_joint" type="continuous">
    <parent link="wheel_rl_axle_link"/>
    <child link="wheel_rl_link"/>
    <origin xyz="0 0 0" rpy="0 0 0"/>
    <axis xyz="0 1 0"/>
    <dynamics damping="0.02" friction="0.01"/>
  </joint>

  <link name="wheel_rl_link">
    <visual>
      <origin xyz="0 0 0" rpy="0 0 0"/>
      <geometry>
        <mesh filename="package://amr_description/meshes/wheel.stl" scale="0.001 0.001 0.001"/>
      </geometry>
    </visual>

    <collision>
      <origin xyz="0 0 0" rpy="1.57 0 0"/>
      <geometry>
        <cylinder length="0.053" radius="0.072"/>
      </geometry>
    </collision>

    <inertial>
      <origin xyz="0 0 0" />
      <mass value="1.12" />
      <inertia ixx="0.0012" ixy="0" ixz="0.0" iyy="0.0021" iyz="0" izz="0.0012"/>
    </inertial>
  </link>
  
  <joint name="wheel_rr_axle_joint" type="fixed">
      <origin xyz="-0.161 -0.167 0.036" rpy="0 0 0"/>
      <parent link="base_link"/>
      <child link="wheel_rr_axle_link"/>
  </joint>
  
  <link name="wheel_rr_axle_link">
    <inertial>
      <mass value="0.1"/>
      <origin xyz="0 0 0"/>
      <inertia ixx="1.0" ixy="0.0" ixz="0.0" iyy="1.0" iyz="0.0" izz="1.0"/>
    </inertial>
    <collision>
        <origin xyz="0 0 0" rpy="1.57 0 0"/>
        <geometry>
          <cylinder length="0.03" radius="0.01"/>
        </geometry>
    </collision>
  </link>
  
  <joint name="wheel_rr_joint" type="continuous">
    <parent link="wheel_rr_axle_link"/>
    <child link="wheel_rr_link"/>
    <origin xyz="0 0 0" rpy="0 0 0"/>
    <axis xyz="0 1 0"/>
    <dynamics damping="0.02" friction="0.01"/>
  </joint>

  <link name="wheel_rr_link">
    <visual>
      <origin xyz="0 0 0" rpy="0 0 0"/>
      <geometry>
        <mesh filename="package://amr_description/meshes/wheel.stl" scale="0.001 0.001 0.001"/>
      </geometry>
    </visual>

    <collision>
      <origin xyz="0 0 0" rpy="1.57 0 0"/>
      <geometry>
        <cylinder length="0.053" radius="0.072"/>
      </geometry>
    </collision>

    <inertial>
      <origin xyz="0 0 0" />
      <mass value="1.12" />
      <inertia ixx="0.0012" ixy="0" ixz="0.0" iyy="0.0021" iyz="0" izz="0.0012"/>
    </inertial>
  </link>
  
  <joint name="imu_joint" type="fixed">
    <parent link="base_link"/>
    <child link="imu_link"/>
    <origin xyz="0 0 0.01" rpy="0 0 0"/>
  </joint>

  <link name="imu_link"/>
<!--
  <joint name="scan_joint" type="fixed">
    <parent link="laser_link"/>
    <child link="base_scan"/>
    <origin xyz="0 0 0.03" rpy="0 0 0"/>
  </joint>
   
  <link name="base_scan"/>
  <joint name="laser_joint" type="fixed">
    <parent link="base_link"/>
    <child link="laser_link"/>
    <origin xyz="0 0 0.29" rpy="0 0 0"/>   -->  <!--  modify height of rp lidar here -->
  <!--
  </joint>
  
  <link name="laser_link">
    <visual>
      <origin xyz="0 0 0" rpy="0 0 0"/>
      <geometry>
        <mesh filename="package://amr_description/meshes/rplidar.stl" scale="0.001 0.001 0.001"/>
      </geometry>
    </visual>

    <collision>
      <origin xyz="0 0 0.02" rpy="0 0 0"/>
      <geometry>
        <cylinder length="0.04" radius="0.04"/>
      </geometry>
    </collision>

    <inertial>
      <mass value="0.166881" />
      <origin xyz="0 0 0" />
      <inertia ixx="0.007841" ixy="0" ixz="0.000033" iyy="0.007681" iyz="0" izz="0.011137"/>
    </inertial>
  </link>
-->
  <!--
  <joint name="camera_joint" type="fixed">
    <origin xyz="0.08 0.0 0.396" rpy="0 0 1.57"/>
    <parent link="base_link"/>
    <child link="camera_link"/>
  </joint>

  <link name="camera_link">
    <visual>
      <origin xyz="0 0 0.0235" rpy="0 0 0"/>
      <geometry>
        <mesh filename="package://amr_description/meshes/asus_camera.stl" scale="0.001 0.001 0.001"/>
      </geometry>
    </visual>

    <collision>
      <origin xyz="0 0 0.0235" rpy="0 0 0"/>
      <geometry>
        <box size="0.04 0.18 0.047"/>
      </geometry>
    </collision>

    <inertial>
      <mass value="0.316" />
      <origin xyz="0 0 0" />
      <inertia ixx="0.0007765" ixy="0" ixz="0" iyy="0.0000725" iyz="0" izz="0.0007657"/>
    </inertial>
  </link>
  
  <joint name="camera_rgb_joint" type="fixed">
    <origin xyz="0 0 0" rpy="0 0 0"/>
    <parent link="camera_link"/>
    <child link="camera_rgb_frame"/>
  </joint>
  
  <link name="camera_rgb_frame"/>

  <joint name="camera_rgb_optical_joint" type="fixed">
    <origin xyz="0 0 0" rpy="-1.57 0 -1.57"/>
    <parent link="camera_rgb_frame"/>
    <child link="camera_rgb_optical_frame"/>
  </joint>
  
  <link name="camera_rgb_optical_frame"/>

  <joint name="camera_depth_joint" type="fixed">
    <origin xyz="0 0 0" rpy="0 0 0"/>
    <parent link="camera_link"/>
    <child link="camera_depth_frame"/>
  </joint>
  
  <link name="camera_depth_frame"/>

  <joint name="camera_depth_optical_joint" type="fixed">
    <origin xyz="0 0 0" rpy="-1.57 0 -1.57"/>
    <parent link="camera_depth_frame"/>
    <child link="camera_depth_optical_frame"/>
  </joint>
  
  <link name="camera_depth_optical_frame"/>
-->
</robot>